<?xml version="1.0" ?>
<!-- =================================================================================== -->
<!-- |    This document was autogenerated by xacro from urdf/akros2_diff/robot.urdf.xacro | -->
<!-- |    EDITING THIS FILE BY HAND IS NOT RECOMMENDED                                 | -->
<!-- =================================================================================== -->
<robot name="akros2_diff">
  <!-- All values below are based on the CAD model (Fusion 360) -->
  <!-- Distance from the motor shaft to the vertical axis -->
  <material name="LaserColor">
    <color rgba="0.2 0.2 0.2 1"/>
  </material>
  <material name="WheelsNavColor">
    <color rgba="0.35 0.35 0.35 1"/>
  </material>
  <material name="BaseLinkColor">
    <color rgba="0.5 0.5 0.5 1"/>
  </material>
  <!-- WHEEL_L TRANSMISSION -->
  <transmission name="trans_l">
    <type>transmission_interface/SimpleTransmission</type>
    <joint name="joint_l">
      <hardwareInterface>hardware_interface/VelocityJointInterface</hardwareInterface>
    </joint>
    <actuator name="motor_l">
      <hardwareInterface>hardware_interface/VelocityJointInterface</hardwareInterface>
      <mechanicalReduction>1</mechanicalReduction>
    </actuator>
  </transmission>
  <!-- WHEEL_R TRANSMISSION -->
  <transmission name="trans_r">
    <type>transmission_interface/SimpleTransmission</type>
    <joint name="joint_r">
      <hardwareInterface>hardware_interface/VelocityJointInterface</hardwareInterface>
    </joint>
    <actuator name="motor_r">
      <hardwareInterface>hardware_interface/VelocityJointInterface</hardwareInterface>
      <mechanicalReduction>1</mechanicalReduction>
    </actuator>
  </transmission>
  <gazebo reference="base_link">
    <material>Gazebo/Grey</material>
  </gazebo>
  <gazebo reference="wheel_l">
    <material>Gazebo/DarkGrey</material>
  </gazebo>
  <gazebo reference="wheel_r">
    <material>Gazebo/DarkGrey</material>
  </gazebo>
  <gazebo>
    <plugin filename="libgazebo_ros_imu.so" name="imu_plugin">
      <alwaysOn>true</alwaysOn>
      <bodyName>imu_link</bodyName>
      <frameName>imu_link</frameName>
      <topicName>imu</topicName>
      <serviceName>imu_service</serviceName>
      <gaussianNoise>0.0</gaussianNoise>
      <updateRate>200</updateRate>
      <imu>
        <noise>
          <type>gaussian</type>
          <rate>
            <mean>0.0</mean>
            <stddev>2e-4</stddev>
            <bias_mean>0.0000075</bias_mean>
            <bias_stddev>0.0000008</bias_stddev>
          </rate>
          <accel>
            <mean>0.0</mean>
            <stddev>1.7e-2</stddev>
            <bias_mean>0.1</bias_mean>
            <bias_stddev>0.001</bias_stddev>
          </accel>
        </noise>
      </imu>
    </plugin>
  </gazebo>
  <gazebo>
    <plugin filename="libgazebo_ros_planar_move.so" name="diff_steering">
      <commandTopic>cmd_vel</commandTopic>
      <odometryTopic>odom</odometryTopic>
      <odometryFrame>odom</odometryFrame>
      <odometryRate>100.0</odometryRate>
      <robotBaseFrame>base_link</robotBaseFrame>
      <publishTF>false</publishTF>
    </plugin>
  </gazebo>
  <!--<gazebo>
  <plugin name="control" filename="libgazebo_ros_control.so"/>
</gazebo>-->
  <!-- **** LINKS **** -->
  <!-- BASE_LINK -->
  <link name="base_link">
    <visual>
      <origin rpy="0 0 0" xyz="0 0 0"/>
      <geometry>
        <mesh filename="package://akros2_description/meshes/akros2_diff/base_module.dae"/>
      </geometry>
      <material name="BaseLinkColor"/>
    </visual>
    <collision>
      <origin rpy="0 0 0" xyz="0 0 0.0164"/>
      <geometry>
        <cylinder length="0.1651" radius="0.105"/>
      </geometry>
    </collision>
  </link>
  <!-- BASE_LINK_INERTIAL (WORKAROUND FOR KDL WHICH DOES NOT ACCEPT BASE_LINK WITH INERTIA) -->
  <link name="base_link_inertial">
    <inertial>
      <origin rpy="0 0 0" xyz="0 0 0"/>
      <mass value="2.0"/>
      <inertia ixx="0.010055501666666666" ixy="0" ixz="0" iyy="0.010055501666666666" iyz="0" izz="0.011024999999999998"/>
    </inertial>
  </link>
  <!-- BASE_FOOTPRINT -->
  <link name="base_footprint"/>
  <!-- BNO055 IMU_LINK -->
  <link name="imu_link"/>
  <!-- WHEEL LEFT -->
  <link name="wheel_l">
    <inertial>
      <mass value="0.075"/>
      <inertia ixx="1.999375e-05" ixy="0" ixz="0" iyy="1.999375e-05" iyz="0" izz="3.15375e-05"/>
    </inertial>
    <visual>
      <origin rpy="0 0 0" xyz="0 0 0"/>
      <geometry>
        <mesh filename="package://akros2_description/meshes/akros2_diff/omniwheel.dae"/>
      </geometry>
      <material name="WheelsNavColor"/>
    </visual>
    <collision>
      <origin rpy="0 1.5707963 0" xyz="0.013 0 0"/>
      <geometry>
        <cylinder length="0.026" radius="0.029"/>
      </geometry>
    </collision>
  </link>
  <!-- WHEEL RIGHT -->
  <link name="wheel_r">
    <inertial>
      <mass value="0.075"/>
      <inertia ixx="1.999375e-05" ixy="0" ixz="0" iyy="1.999375e-05" iyz="0" izz="3.15375e-05"/>
    </inertial>
    <visual>
      <origin rpy="0 0 0" xyz="0 0 0"/>
      <geometry>
        <mesh filename="package://akros2_description/meshes/akros2_diff/omniwheel.dae"/>
      </geometry>
      <material name="WheelsNavColor"/>
    </visual>
    <collision>
      <origin rpy="0 1.5707963 0" xyz="0.013 0 0"/>
      <geometry>
        <cylinder length="0.026" radius="0.029"/>
      </geometry>
    </collision>
  </link>
  <!-- **** JOINTS **** -->
  <!-- BASE_LINK_INERTIAL TO BASE_LINK -->
  <joint name="base_inertial_fixed" type="fixed">
    <parent link="base_link"/>
    <child link="base_link_inertial"/>
    <origin xyz="0 0 0"/>
  </joint>
  <!-- BASE_FOOTPRINT TO BASE_LINK -->
  <joint name="base_footprint_fixed" type="fixed">
    <parent link="base_link"/>
    <child link="base_footprint"/>
    <origin xyz="0 0 0.085597"/>
  </joint>
  <!-- IMU_LINK TO BASE_LINK -->
  <joint name="imu_base_fixed" type="fixed">
    <parent link="base_link"/>
    <child link="imu_link"/>
    <origin xyz="0 0 0.063003"/>
  </joint>
  <!-- WHEEL_L TO BASE_LINK -->
  <joint name="joint_l" type="continuous">
    <parent link="base_link"/>
    <child link="wheel_l"/>
    <origin rpy="0 0 2.094395" xyz="-0.053415 0.092518 -0.056597"/>
    <axis xyz="1 0 0"/>
  </joint>
  <!-- WHEEL_R TO BASE_LINK -->
  <joint name="joint_r" type="continuous">
    <parent link="base_link"/>
    <child link="wheel_r"/>
    <origin rpy="0 0 -2.094395" xyz="-0.053415 -0.092518 -0.056597"/>
    <axis xyz="1 0 0"/>
  </joint>
</robot>
